Workbook

Sheet Como usar
B1: Como usar este ficheiro
B2: O ficheiro reúne 224 estágios e programas de entrada com início em janeiro de 2027 (ou perto), sobretudo em private equity, M&A, banca de investimento e gestão de ativos, em Portugal e na Europa. Para cada vaga estima o encaixe com o teu CV e a probabilidade de seres aceite. Cada vaga tem link de candidatura.
B4: As folhas
B5: Resumo | C5: Visão geral numa página: números-chave, vagas por país, as 10 melhores candidaturas e notas importantes. Começa aqui.
B6: Decisão | C6: Uma linha por vaga, ordenada por probabilidade × interesse. É a folha para decidir: filtra por veredicto, país ou chance e usa 'Abrir' para ir ao link.
B7: Dados completos | C7: Toda a informação, vaga a vaga: descrição, requisitos, prazo, salário bruto estimado, fatores do match e notas. Passa o rato por cima dos cabeçalhos para veres o significado das colunas principais.
B8: Perfil e pressupostos | C8: O teu perfil, as línguas, os pesos do match e as taxas base de aceitação. As células a azul são editáveis e todo o ficheiro recalcula.
B9: Análise de match | C9: Estatística sobre as melhores vagas: Top 10, médias por país e dificuldade, quantas candidaturas fazer, sensibilidade aos pressupostos e correlações. Tem dois gráficos.
B11: Os gráficos
B12: Vagas por país (Resumo) | C12: Barras horizontais com o número de vagas listadas em cada país. Mostra onde está a oferta.
B13: Top 10: probabilidade estimada (Análise de match) | C13: Uma barra por vaga do Top 10, com a probabilidade estimada de aceitação. Serve para comparar as melhores vagas entre si.
B14: Prob. de ≥1 oferta vs. nº de candidaturas (Análise de match) | C14: Linha que mostra como sobe a probabilidade de receberes pelo menos uma oferta à medida que te candidatas a mais vagas (sempre às melhores do ranking). A curva tende a achatar: as candidaturas seguintes valem cada vez menos.
B16: Glossário
B17: Tipo de empresa | C17: Banca de investimento, boutique de M&A, VC e private equity, banca comercial, Big 4 e consultoria, big corporate, startup ou scale-up, PME, seguradora, serviços financeiros ou setor público.
B18: Veredicto | C18: Prioridade: score de 3,5 ou mais. Candidatar (reach): 3,0 a 3,4. Reserva: abaixo de 3. Monitorizar: vaga ainda não aberta. Prazo passado: já fechou.
B19: Score (60% fit + 40% facilidade) | C19: 0,6 × Fit + 0,4 × Facilidade. Vai de 1 a 5.
B20: Fit com PE/Finance (1-5) | C20: Quanto a vaga serve o teu interesse em private equity e finanças (5 = PE puro).
B21: Facilidade (1-5) | C21: Quão fácil é ser aceite, tendo em conta a dificuldade da vaga e o encaixe com o teu CV (5 = mais fácil).
B22: Match com o CV (0-100) | C22: Encaixe do teu CV com a vaga: média ponderada de Idioma, Experiência, Elegibilidade e Perfil. Os pesos estão em 'Perfil e pressupostos'.
B23: Prob. estimada de aceitação | C23: Estimativa comparativa: taxa base da dificuldade × fator do match. Não é uma estatística oficial.
B24: Chance | C24: Boa: 8% ou mais. Média: 3% a 8%. Baixa: menos de 3%.
B25: Dificuldade de ser aceite | C25: Julgamento meu sobre a concorrência: Muito alta, Alta, Média-alta ou Média.
B26: Qualidade da informação | C26: Verificada na página: li a oferta. Parcial: só título ou agregador. Por confirmar: indício fraco.
B27: Tipo de link | C27: Direto: site ou sistema de recrutamento da empresa. Anúncio em plataforma: JobTeaser, eFinancialCareers, etc. Página de carreiras: tens de procurar a vaga.
B28: Língua-chave | C28: A língua que mais pesa na vaga. A proficiência de cada língua está em 'Perfil e pressupostos'.
... B30: Probabilidade de ≥1 oferta | C30: Probabilidade de receberes pelo menos uma oferta com N candidaturas, tendo em conta que as candidaturas não são independentes (o mesmo CV é lido em todas).
B32: Como usar, passo a passo
B33: 1. Ver o Resumo | C33: Percebe o panorama geral e lê as notas no fim da folha.
B34: 2. Filtrar na Decisão | C34: Usa o filtro do cabeçalho para ver só 'Prioridade' ou 'Candidatar (reach)' e, se quiseres, só um país ou só chance 'Boa'.
B35: 3. Abrir o link | C35: Confirma o prazo, a elegibilidade e a língua na oferta. Nas vagas 'Parcial' a descrição aqui é genérica.
B36: 4. Ajustar o perfil | C36: Se melhorares uma língua ou ganhares experiência, muda os valores em 'Perfil e pressupostos' e os resultados recalculam.
B37: 5. Candidatar-te | C37: Começa pelas candidaturas 'rolling', que fecham quando a vaga é preenchida, e pelas com prazo mais próximo.
B39: Limites a ter em conta
B40: Probabilidades | C40: São estimativas comparativas, assentes em taxas base que eu assumi. Servem para ordenar vagas e não para prever resultados.
B41: Informação das vagas | C41: Muitas vagas só foram vistas em agregadores ou em páginas que não consegui abrir. Confirma sempre na oferta.
B42: Salários (valores brutos) | C42: Todos os valores são brutos mensais, antes de impostos e descontos. São estimativas de mercado, exceto o EIB (1.500 €/mês; a fonte não diz se é bruto ou líquido) e o IEFP (1.181,69 € brutos, bolsa de nível 6). Em Portugal, o valor líquido fica abaixo do bruto por causa dos descontos para a Segurança Social e do IRS.
B43: Atualização | C43: Pesquisa feita a 17-10-2026. Os prazos mudam e as vagas rolling fecham sem aviso.

Sheet Resumo
B1: Estágios de 6 meses · entrada em janeiro 2027
B2: Private equity, M&A e banca de investimento, gestão de ativos e finanças · Portugal e Europa · pesquisa de 17-10-2026 · inclui o encaixe com o teu CV
B3: Esta folha é o ponto de partida: números gerais, vagas por país e as 10 melhores candidaturas. Depois passa à folha Decisão para escolher vaga a vaga.
B4: Números-chave | E4: Por país | J4: Gráfico de barras: número de vagas listadas por país (inclui também as de prazo passado). Mostra onde está concentrada a oferta: a França e o Reino Unido dominam.
B5: Vagas e oportunidades listadas | C5: =COUNTA('Dados completos'!$B$4:$B$227) -> 224 | E5: País | F5: Nº | G5: Prob. média | H5: Chance Boa
B6: Com estado 'Aberta' (rolling ou com prazo) | C6: =COUNTIF('Dados completos'!$AK$4:$AK$227,"Aberta*") -> 35 | E6: Reino Unido | F6: =COUNTIF('Dados completos'!$F$4:$F$227,E6) -> 28 | G6: =IFERROR(AVERAGEIFS('Dados completos'!$AR$4:$AR$227,'Dados completos'!$F$4:$F$227,E6,'Dados completos'!$AQ$4:$AQ$227,1),"") -> 0.014680741 | H6: =COUNTIFS('Dados completos'!$F$4:$F$227,E6,'Dados completos'!$AI$4:$AI$227,"Boa") -> 0
B7: Por confirmar (visto em agregadores) | C7: =COUNTIF('Dados completos'!$AK$4:$AK$227,"Por confirmar") -> 160 | E7: Espanha | F7: =COUNTIF('Dados completos'!$F$4:$F$227,E7) -> 8 | G7: =IFERROR(AVERAGEIFS('Dados completos'!$AR$4:$AR$227,'Dados completos'!$F$4:$F$227,E7,'Dados completos'!$AQ$4:$AQ$227,1),"") -> 0.018547429 | H7: =COUNTIFS('Dados completos'!$F$4:$F$227,E7,'Dados completos'!$AI$4:$AI$227,"Boa") -> 0
B8: Prazo já expirado | C8: =COUNTIF('Dados completos'!$AK$4:$AK$227,"Prazo expirado") -> 7 | E8: França | F8: =COUNTIF('Dados completos'!$F$4:$F$227,E8) -> 62 | G8: =IFERROR(AVERAGEIFS('Dados completos'!$AR$4:$AR$227,'Dados completos'!$F$4:$F$227,E8,'Dados completos'!$AQ$4:$AQ$227,1),"") -> 0.016289967 | H8: =COUNTIFS('Dados completos'!$F$4:$F$227,E8,'Dados completos'!$AI$4:$AI$227,"Boa") -> 0
B9: Veredicto 'Prioridade' (fit + facilidade) | C9: =COUNTIF('Dados completos'!$AL$4:$AL$227,"Prioridade") -> 31 | E9: Alemanha | F9: =COUNTIF('Dados completos'!$F$4:$F$227,E9) -> 19 | G9: =IFERROR(AVERAGEIFS('Dados completos'!$AR$4:$AR$227,'Dados completos'!$F$4:$F$227,E9,'Dados completos'!$AQ$4:$AQ$227,1),"") -> 0.013674284 | H9: =COUNTIFS('Dados completos'!$F$4:$F$227,E9,'Dados completos'!$AI$4:$AI$227,"Boa") -> 0
B10: Chance 'Boa' (match com o CV) | C10: =COUNTIF('Dados completos'!$AI$4:$AI$227,"Boa") -> 43 | E10: Portugal | F10: =COUNTIF('Dados completos'!$F$4:$F$227,E10) -> 73 | G10: =IFERROR(AVERAGEIFS('Dados completos'!$AR$4:$AR$227,'Dados completos'!$F$4:$F$227,E10,'Dados completos'!$AQ$4:$AQ$227,1),"") -> 0.12364477 | H10: =COUNTIFS('Dados completos'!$F$4:$F$227,E10,'Dados completos'!$AI$4:$AI$227,"Boa") -> 42
B11: Match médio com o CV (0-100) | C11: ='Análise de match'!D21 -> 58.32425 | E11: Luxemburgo | F11: =COUNTIF('Dados completos'!$F$4:$F$227,E11) -> 6 | G11: =IFERROR(AVERAGEIFS('Dados completos'!$AR$4:$AR$227,'Dados completos'!$F$4:$F$227,E11,'Dados completos'!$AQ$4:$AQ$227,1),"") -> 0.052449667 | H11: =COUNTIFS('Dados completos'!$F$4:$F$227,E11,'Dados completos'!$AI$4:$AI$227,"Boa") -> 1
B12: Prob. de ≥1 oferta com as 10 melhores candidaturas | C12: ='Análise de match'!D62 -> 0.55110146 | E12: Suécia | F12: =COUNTIF('Dados completos'!$F$4:$F$227,E12) -> 4 | G12: =IFERROR(AVERAGEIFS('Dados completos'!$AR$4:$AR$227,'Dados completos'!$F$4:$F$227,E12,'Dados completos'!$AQ$4:$AQ$227,1),"") -> 0.0112585 | H12: =COUNTIFS('Dados completos'!$F$4:$F$227,E12,'Dados completos'!$AI$4:$AI$227,"Boa") -> 0
B13: Prob. de ≥1 oferta com as 20 melhores candidaturas | C13: ='Análise de match'!D64 -> 0.79373891 | E13: Suíça | F13: =COUNTIF('Dados completos'!$F$4:$F$227,E13) -> 9 | G13: =IFERROR(AVERAGEIFS('Dados completos'!$AR$4:$AR$227,'Dados completos'!$F$4:$F$227,E13,'Dados completos'!$AQ$4:$AQ$227,1),"") -> 0.015308444 | H13: =COUNTIFS('Dados completos'!$F$4:$F$227,E13,'Dados completos'!$AI$4:$AI$227,"Boa") -> 0
B14: Em Portugal | C14: =COUNTIF('Dados completos'!$F$4:$F$227,"Portugal") -> 73 | E14: Itália | F14: =COUNTIF('Dados completos'!$F$4:$F$227,E14) -> 8 | G14: =IFERROR(AVERAGEIFS('Dados completos'!$AR$4:$AR$227,'Dados completos'!$F$4:$F$227,E14,'Dados completos'!$AQ$4:$AQ$227,1),"") -> 0.014724 | H14: =COUNTIFS('Dados completos'!$F$4:$F$227,E14,'Dados completos'!$AI$4:$AI$227,"Boa") -> 0
E15: Polónia | F15: =COUNTIF('Dados completos'!$F$4:$F$227,E15) -> 1 | G15: =IFERROR(AVERAGEIFS('Dados completos'!$AR$4:$AR$227,'Dados completos'!$F$4:$F$227,E15,'Dados completos'!$AQ$4:$AQ$227,1),"") -> 0.03405 | H15: =COUNTIFS('Dados completos'!$F$4:$F$227,E15,'Dados completos'!$AI$4:$AI$227,"Boa") -> 0
E16: Bélgica | F16: =COUNTIF('Dados completos'!$F$4:$F$227,E16) -> 1 | G16: =IFERROR(AVERAGEIFS('Dados completos'!$AR$4:$AR$227,'Dados completos'!$F$4:$F$227,E16,'Dados completos'!$AQ$4:$AQ$227,1),"") -> 0.01126 | H16: =COUNTIFS('Dados completos'!$F$4:$F$227,E16,'Dados completos'!$AI$4:$AI$227,"Boa") -> 0
E17: Países Baixos | F17: =COUNTIF('Dados completos'!$F$4:$F$227,E17) -> 5 | G17: =IFERROR(AVERAGEIFS('Dados completos'!$AR$4:$AR$227,'Dados completos'!$F$4:$F$227,E17,'Dados completos'!$AQ$4:$AQ$227,1),"") -> 0.0195264 | H17: =COUNTIFS('Dados completos'!$F$4:$F$227,E17,'Dados completos'!$AI$4:$AI$227,"Boa") -> 0
B20: Top 10 por probabilidade × interesse (ver 'Análise de match')
B21: Empresa, role | C21: Cidade | D21: Modalidade | E21: Dificuldade | F21: Prob. aceit. | G21: Match CV | H21: Chance
B22: =Decisão!G5&", "&Decisão!H5 -> Santander Portugal, Estágio, Controlo e Governo de Riscos | C22: =Decisão!K5 -> Lisboa | D22: =Decisão!L5 -> Não indicado (provável presencial) | E22: =Decisão!O5 -> Média | F22: =Decisão!E5 -> 0.17904 | G22: =Decisão!D5 -> 91 | H22: =Decisão!F5 -> Boa
B23: =Decisão!G6&", "&Decisão!H6 -> Santander Portugal, Credit Risk Trainee | C23: =Decisão!K6 -> Lisboa | D23: =Decisão!L6 -> Não indicado (provável presencial) | E23: =Decisão!O6 -> Média | F23: =Decisão!E6 -> 0.17904 | G23: =Decisão!D6 -> 91 | H23: =Decisão!F6 -> Boa
B24: =Decisão!G7&", "&Decisão!H7 -> Banco Santander (Portugal), Programa de Estágios, Candidatura espontânea (Lisboa) | C24: =Decisão!K7 -> Lisboa | D24: =Decisão!L7 -> Não indicado (provável presencial) | E24: =Decisão!O7 -> Média | F24: =Decisão!E7 -> 0.17688 | G24: =Decisão!D7 -> 89.5 | H24: =Decisão!F7 -> Boa
B25: =Decisão!G8&", "&Decisão!H8 -> Qualquer empresa portuguesa (PE/VC/Corporate Finance), Estágio profissional via IEFP (Estágios +Talento) + candidatura espontânea | C25: =Decisão!K8 -> Lisboa (e outras) | D25: =Decisão!L8 -> Depende da empresa | E25: =Decisão!O8 -> Média | F25: =Decisão!E8 -> 0.17688 | G25: =Decisão!D8 -> 89.5 | H25: =Decisão!F8 -> Boa
B26: =Decisão!G9&", "&Decisão!H9 -> Caixa Geral de Depósitos, Estagiário(a), Direção de Mercados Financeiros | C26: =Decisão!K9 -> Lisboa | D26: =Decisão!L9 -> Não indicado (provável presencial) | E26: =Decisão!O9 -> Média-alta | F26: =Decisão!E9 -> 0.1172 | G26: =Decisão!D9 -> 88.75 | H26: =Decisão!F9 -> Boa
B27: =Decisão!G10&", "&Decisão!H10 -> EY-Parthenon, Business Analyst, EY-Parthenon M&A (Real Estate) (Lisboa) | C27: =Decisão!K10 -> Lisboa | D27: =Decisão!L10 -> Híbrido | E27: =Decisão!O10 -> Média-alta | F27: =Decisão!E10 -> 0.11792 | G27: =Decisão!D10 -> 89.5 | H27: =Decisão!F10 -> Boa
B28: =Decisão!G11&", "&Decisão!H11 -> BNP Paribas, Investment Banking Trainee, M&A Advisory (Lisboa) | C28: =Decisão!K11 -> Lisboa | D28: =Decisão!L11 -> Híbrido | E28: =Decisão!O11 -> Média-alta | F28: =Decisão!E11 -> 0.11648 | G28: =Decisão!D11 -> 88 | H28: =Decisão!F11 -> Boa
B29: =Decisão!G12&", "&Decisão!H12 -> Empresa por confirmar (gestora), Data Analyst Trainee, Real Assets (Lisboa) | C29: =Decisão!K12 -> Lisboa | D29: =Decisão!L12 -> Não indicado (provável presencial) | E29: =Decisão!O12 -> Média-alta | F29: =Decisão!E12 -> 0.116048 | G29: =Decisão!D12 -> 87.55 | H29: =Decisão!F12 -> Boa
B30: =Decisão!G13&", "&Decisão!H13 -> Euronext, Early Careers (programa de 2 anos nos mercados financeiros europeus) | C30: =Decisão!K13 -> Lisboa | D30: =Decisão!L13 -> Não indicado (provável presencial) | E30: =Decisão!O13 -> Média-alta | F30: =Decisão!E13 -> 0.115664 | G30: =Decisão!D13 -> 87.15 | H30: =Decisão!F13 -> Boa
B31: =Decisão!G14&", "&Decisão!H14 -> Hilton, Finance Intern / Trainee (Lisboa) | C31: =Decisão!K14 -> Lisboa | D31: =Decisão!L14 -> Não indicado (provável presencial) | E31: =Decisão!O14 -> Média | F31: =Decisão!E14 -> 0.179472 | G31: =Decisão!D14 -> 91.3 | H31: =Decisão!F14 -> Boa
B34: O que tens de saber antes de candidatar
B35: 1. Encaixe com o CV: o teu CV mostra liderança, logística, angariação de fundos, Excel certificado, Python e inglês C1, mas nenhum estágio em finanças nem francês ou alemão. Por isso o match é mais baixo nas vagas de PE em Paris e Frankfurt e nas que pedem experiência prévia. O cálculo está em 'Perfil e pressupostos' e 'Análise de match'.
B36: 2. Acabas o curso em janeiro e muitos programas off-cycle pedem que ainda estejas inscrita (a BlackRock exige o penúltimo ano; a Houlihan Lokey e a Ardian pedem mestrado ou convenção de estágio). Os que aceitam recém-licenciadas (Alantra Madrid, EIB, Blackstone, estágio IEFP, BNP) são os mais seguros.
B37: 3. Portugal tem poucas vagas públicas de PE e de banca de investimento. A melhor é a BNP Paribas Lisboa (M&A Advisory, híbrido). Para PE português, a via mais realista é a candidatura espontânea com o estágio IEFP (bolsa de 1.181,69 € brutos, em parte financiada pelo Estado; as empresas candidatam-se até 07-12-2026).
B38: 4. Salários: todos os valores são brutos mensais. Só o EIB (1.500 €/mês, bruto ou líquido não especificado pela fonte) e o IEFP (1.181,69 € brutos) vêm de fonte oficial. Os restantes são estimativas de mercado (ver a coluna sobre a fonte do salário bruto em 'Dados completos').
B39: 5. Prazos conhecidos: Houlihan Lokey Zurique 21-10-2026; Mastercard Lisboa 25-10-2026; Citi Zurique 06-11-2026; J.P. Morgan Estocolmo 07-11-2026; BlackRock Frankfurt e Munique 13-11-2026; MUFG Amesterdão 15-11-2026; Astorg Frankfurt 30-11-2026; IEFP (empresas) 07-12-2026. As candidaturas 'rolling' fecham quando a vaga é preenchida, por isso candidata-te cedo.
B40: 6. Qualidade da informação: 'Verificada na página' quer dizer que li a oferta. 'Parcial' quer dizer que só vi o título ou um agregador, ou que não consegui abrir a página; nesses casos a descrição e os requisitos são os típicos da categoria e dizem 'ver oferta'. 'Por confirmar' é um indício fraco. A maioria das vagas novas é 'Parcial', por isso confirma o prazo, a elegibilidade e a língua no link antes de te candidatares.
B41: 7. Links: cada vaga tem um link de candidatura (coluna 'Link' e botão 'Abrir'). A coluna 'Tipo de link' diz se é direto (site ou sistema de recrutamento da empresa), um anúncio numa plataforma (JobTeaser, eFinancialCareers, etc.) ou uma página de carreiras onde tens de procurar a vaga (UBS, Wells Fargo, Mizuho, Natixis, Evercore Londres).
B42: 8. Dificuldade, fit, facilidade e os fatores do match são julgamento meu (a azul, editáveis). As probabilidades servem para comparar vagas e não são estatísticas oficiais de aceitação.
B43: 9. Portugal: acrescentei vagas de bancos, Big 4, seguradoras, grandes empresas, scale-ups e candidaturas espontâneas a gestoras de VC. Muitos programas de trainees portugueses abrem de março a maio para entrada em setembro, por isso aparecem como 'Monitorizar' e não entram nos rankings até abrirem. Os que estão abertos agora (CGD, Jerónimo Martins, Coca-Cola, CP, Deloitte, BNP Paribas) são os mais urgentes.
B45: Deixei de fora: a DPE (o link é de 2026), a Mastercard de verão, funções jurídicas, de operações ou de wealth management, estágios só de verão, a Tikehau Bruxelas (fechada, pede neerlandês), a Cinven Londres (removida a 06-10-2026, pede neerlandês) e a Schroders Zurique (working student de 12 meses).
...

Sheet Decisão
A1: Vista de decisão, vaga a vaga (ordenada por probabilidade × interesse)
A2: Uma linha por vaga, ordenada por probabilidade de aceitação × interesse. O veredicto junta interesse e facilidade (Score = 60% fit com PE e finanças + 40% facilidade). Match CV mede o encaixe do teu CV (0 a 100) e Prob. é uma estimativa comparativa, explicada em 'Perfil e pressupostos'. Os valores vêm de 'Dados completos'. A ordem ficou fixa na criação: usa o filtro do cabeçalho para reordenar. O botão 'Abrir' leva ao link da candidatura.
A4: # | B4: Veredicto | C4: Score | D4: Match CV | E4: Prob. aceitação | F4: Chance | G4: Empresa | H4: Role | I4: Tipo empresa | J4: País | K4: Cidade | L4: Modalidade | M4: Início | N4: Deadline | O4: Dificuldade | P4: Salário bruto est. (€/mês) | Q4: Idiomas | R4: Porquê (CV) | S4: Estado | T4: Info | U4: Tipo link | V4: Link
A5: ='Dados completos'!A178 -> 175 | B5: ='Dados completos'!AL178 -> Candidatar (reach) | C5: ='Dados completos'!Y178 -> 3.4 | D5: ='Dados completos'!AF178 -> 91 | E5: ='Dados completos'!AH178 -> 0.17904 | F5: ='Dados completos'!AI178 -> Boa | G5: ='Dados completos'!B178 -> Santander Portugal | H5: ='Dados completos'!C178 -> Estágio, Controlo e Governo de Riscos | I5: ='Dados completos'!E178 -> Banca comercial | J5: ='Dados completos'!F178 -> Portugal | K5: ='Dados completos'!G178 -> Lisboa | L5: ='Dados completos'!H178 -> Não indicado (provável presencial) | M5: ='Dados completos'!I178 -> Não indicado | N5: ='Dados completos'!O178 -> Não indicado | O5: ='Dados completos'!V178 -> Média | P5: =IF('Dados completos'!R178="","n/d",IF('Dados completos'!R178='Dados completos'!S178,TEXT('Dados completos'!R178,"#,##0"),TEXT('Dados completos'!R178,"#,##0")&", "&TEXT('Dados completos'!S178,"#,##0"))) -> 1,000, 1,300 | Q5: ='Dados completos'!M178 -> Inglês (ver oferta) | R5: ='Dados completos'!AJ178 -> Língua-chave PT (exigência 0.3); não exige experiência prévia em finanças; aceita recém-licenciadas. | S5: ='Dados completos'!AK178 -> Por confirmar | T5: ='Dados completos'!AP178 -> Parcial (agregador/título) | U5: ='Dados completos'!AO178 -> Anúncio em plataforma | V5: =HYPERLINK('Dados completos'!AN178,"Abrir") -> Abrir
A6: ='Dados completos'!A179 -> 176 | B6: ='Dados completos'!AL179 -> Candidatar (reach) | C6: ='Dados completos'!Y179 -> 3.4 | D6: ='Dados completos'!AF179 -> 91 | E6: ='Dados completos'!AH179 -> 0.17904 | F6: ='Dados completos'!AI179 -> Boa | G6: ='Dados completos'!B179 -> Santander Portugal | H6: ='Dados completos'!C179 -> Credit Risk Trainee | I6: ='Dados completos'!E179 -> Banca comercial | J6: ='Dados completos'!F179 -> Portugal | K6: ='Dados completos'!G179 -> Lisboa | L6: ='Dados completos'!H179 -> Não indicado (provável presencial) | M6: ='Dados completos'!I179 -> Não indicado | N6: ='Dados completos'!O179 -> Não indicado | O6: ='Dados completos'!V179 -> Média | P6: =IF('Dados completos'!R179="","n/d",IF('Dados completos'!R179='Dados completos'!S179,TEXT('Dados completos'!R179,"#,##0"),TEXT('Dados completos'!R179,"#,##0")&", "&TEXT('Dados completos'!S179,"#,##0"))) -> 1,000, 1,300 | Q6: ='Dados completos'!M179 -> Inglês (ver oferta) | R6: ='Dados completos'!AJ179 -> Língua-chave PT (exigência 0.3); não exige experiência prévia em finanças; aceita recém-licenciadas. | S6: ='Dados completos'!AK179 -> Por confirmar | T6: ='Dados completos'!AP179 -> Parcial (agregador/título) | U6: ='Dados completos'!AO179 -> Anúncio em plataforma | V6: =HYPERLINK('Dados completos'!AN179,"Abrir") -> Abrir
A7: ='Dados completos'!A38 -> 35 | B7: ='Dados completos'!AL38 -> Candidatar (reach) | C7: ='Dados completos'!Y38 -> 3.4 | D7: ='Dados completos'!AF38 -> 89.5 | E7: ='Dados completos'!AH38 -> 0.17688 | F7: ='Dados completos'!AI38 -> Boa | G7: ='Dados completos'!B38 -> Banco Santander (Portugal) | H7: ='Dados completos'!C38 -> Programa de Estágios, Candidatura espontânea (Lisboa) | I7: ='Dados completos'!E38 -> Banca comercial | J7: ='Dados completos'!F38 -> Portugal | K7: ='Dados completos'!G38 -> Lisboa | L7: ='Dados completos'!H38 -> Não indicado (provável presencial) | M7: ='Dados completos'!I38 -> Flexível | N7: ='Dados completos'!O38 -> Aberta (espontânea) | O7: ='Dados completos'!V38 -> Média | P7: =IF('Dados completos'!R38="","n/d",IF('Dados completos'!R38='Dados completos'!S38,TEXT('Dados completos'!R38,"#,##0"),TEXT('Dados completos'!R38,"#,##0")&", "&TEXT('Dados completos'!S38,"#,##0"))) -> 1,000, 1,300 | Q7: ='Dados completos'!M38 -> Português e inglês | R7: ='Dados completos'!AJ38 -> Língua-chave PT (exigência 1); não exige experiência prévia em finanças; aceita recém-licenciadas. | S7: ='Dados completos'!AK38 -> Aberta (rolling) | T7: ='Dados completos'!AP38 -> Parcial (agregador/título) | U7: ='Dados completos'!AO38 -> Página de carreiras (procurar a vaga) | V7: =HYPERLINK('Dados completos'!AN38,"Abrir") -> Abrir
A8: ='Dados completos'!A40 -> 37 | B8: ='Dados completos'!AL40 -> Prioridade | C8: ='Dados completos'!Y40 -> 3.6 | D8: ='Dados completos'!AF40 -> 89.5 | E8: ='Dados completos'!AH40 -> 0.17688 | F8: ='Dados completos'!AI40 -> Boa | G8: ='Dados completos'!B40 -> Qualquer empresa portuguesa (PE/VC/Corporate Finance) | H8: ='Dados completos'!C40 -> Estágio profissional via IEFP (Estágios +Talento) + candidatura espontânea | I8: ='Dados completos'!E40 -> Via de acesso | J8: ='Dados completos'!F40 -> Portugal | K8: ='Dados completos'!G40 -> Lisboa (e outras) | L8: ='Dados completos'!H40 -> Depende da empresa | M8: ='Dados completos'!I40 -> Flexível (empresa candidata 12-10 a 07-12-2026) | N8: ='Dados completos'!O40 -> 07-12-2026 (janela da empresa) | O8: ='Dados completos'!V40 -> Média | P8: =IF('Dados completos'!R40="","n/d",IF('Dados completos'!R40='Dados completos'!S40,TEXT('Dados completos'!R40,"#,##0"),TEXT('Dados completos'!R40,"#,##0")&", "&TEXT('Dados completos'!S40,"#,##0"))) -> 1,182 | Q8: ='Dados completos'!M40 -> Português | R8: ='Dados completos'!AJ40 -> Língua-chave PT (exigência 1); não exige experiência prévia em finanças; aceita recém-licenciadas. | S8: ='Dados completos'!AK40 -> Via a explorar | T8: ='Dados completos'!AP40 -> Verificada na página | U8: ='Dados completos'!AO40 -> Página de carreiras (procurar a vaga) | V8: =HYPERLINK('Dados completos'!AN40,"Abrir") -> Abrir
A9: ='Dados completos'!A174 -> 171 | B9: ='Dados completos'!AL174 -> Prioridade | C9: ='Dados completos'!Y174 -> 4.2 | D9: ='Dados completos'!AF174 -> 88.75 | E9: ='Dados completos'!AH174 -> 0.1172 | F9: ='Dados completos'!AI174 -> Boa | G9: ='Dados completos'!B174 -> Caixa Geral de Depósitos | H9: ='Dados completos'!C174 -> Estagiário(a), Direção de Mercados Financeiros | I9: ='Dados completos'!E174 -> Banca comercial | J9: ='Dados completos'!F174 -> Portugal | K9: ='Dados completos'!G174 -> Lisboa | L9: ='Dados completos'!H174 -> Não indicado (provável presencial) | M9: ='Dados completos'!I174 -> Não indicado | N9: ='Dados completos'!O174 -> Não indicado | O9: ='Dados completos'!V174 -> Média-alta | P9: =IF('Dados completos'!R174="","n/d",IF('Dados completos'!R174='Dados completos'!S174,TEXT('Dados completos'!R174,"#,##0"),TEXT('Dados completos'!R174,"#,##0")&", "&TEXT('Dados completos'!S174,"#,##0"))) -> 1,000, 1,300 | Q9: ='Dados completos'!M174 -> Português e inglês | R9: ='Dados completos'!AJ174 -> Língua-chave PT (exigência 0.3); não exige experiência prévia em finanças; aceita recém-licenciadas. | S9: ='Dados completos'!AK174 -> Aberta (prazo não indicado) | T9: ='Dados completos'!AP174 -> Parcial (agregador/título) | U9: ='Dados completos'!AO174 -> Direto (site/ATS da empresa) | V9: =HYPERLINK('Dados completos'!AN174,"Abrir") -> Abrir
A10: ='Dados completos'!A16 -> 13 | B10: ='Dados completos'!AL16 -> Prioridade | C10: ='Dados completos'!Y16 -> 3.8 | D10: ='Dados completos'!AF16 -> 89.5 | E10: ='Dados completos'!AH16 -> 0.11792 | F10: ='Dados completos'!AI16 -> Boa | G10: ='Dados completos'!B16 -> EY-Parthenon | H10: ='Dados completos'!C16 -> Business Analyst, EY-Parthenon M&A (Real Estate) (Lisboa) | I10: ='Dados completos'!E16 -> Big 4 / consultoria | J10: ='Dados completos'!F16 -> Portugal | K10: ='Dados completos'!G16 -> Lisboa | L10: ='Dados completos'!H16 -> Híbrido | M10: ='Dados completos'!I16 -> Imediato | N10: ='Dados completos'!O16 -> Não indicado (publicada 11-08-2026) | O10: ='Dados completos'!V16 -> Média-alta | P10: =IF('Dados completos'!R16="","n/d",IF('Dados completos'!R16='Dados completos'!S16,TEXT('Dados completos'!R16,"#,##0"),TEXT('Dados completos'!R16,"#,##0")&", "&TEXT('Dados completos'!S16,"#,##0"))) -> 1,300, 1,800 | Q10: ='Dados completos'!M16 -> Inglês e português | R10: ='Dados completos'!AJ16 -> Língua-chave EN (exigência 1); não exige experiência prévia em finanças; aceita recém-licenciadas. | S10: ='Dados completos'!AK16 -> Aberta (prazo não indicado) | T10: ='Dados completos'!AP16 -> Parcial (agregador/título) | U10: ='Dados completos'!AO16 -> Página de carreiras (procurar a vaga) | V10: =HYPERLINK('Dados completos'!AN16,"Abrir") -> Abrir
A11: ='Dados completos'!A15 -> 12 | B11: ='Dados completos'!AL15 -> Prioridade | C11: ='Dados completos'!Y15 -> 4 | D11: ='Dados completos'!AF15 -> 88 | E11: ='Dados completos'!AH15 -> 0.11648 | F11: ='Dados completos'!AI15 -> Boa | G11: ='Dados completos'!B15 -> BNP Paribas | H11: ='Dados completos'!C15 -> Investment Banking Trainee, M&A Advisory (Lisboa) | I11: ='Dados completos'!E15 -> Banca de investimento | J11: ='Dados completos'!F15 -> Portugal | K11: ='Dados completos'!G15 -> Lisboa | L11: ='Dados completos'!H15 -> Híbrido | M11: ='Dados completos'!I15 -> Não indicado (confirmar) | N11: ='Dados completos'!O15 -> Não indicado | O11: ='Dados completos'!V15 -> Média-alta | P11: =IF('Dados completos'!R15="","n/d",IF('Dados completos'!R15='Dados completos'!S15,TEXT('Dados completos'!R15,"#,##0"),TEXT('Dados completos'!R15,"#,##0")&", "&TEXT('Dados completos'!S15,"#,##0"))) -> 1,000, 1,400 | Q11: ='Dados completos'!M15 -> Inglês fluente (português) | R11: ='Dados completos'!AJ15 -> Língua-chave EN (exigência 1); não exige experiência prévia em finanças; aceita recém-licenciadas. | S11: ='Dados completos'!AK15 -> Aberta (prazo não indicado) | T11: ='Dados completos'!AP15 -> Verificada na página | U11: ='Dados completos'!AO15 -> Direto (site/ATS da empresa) | V11: =HYPERLINK('Dados completos'!AN15,"Abrir") -> Abrir
A12: ='Dados completos'!A195 -> 192 | B12: ='Dados completos'!AL195 -> Prioridade | C12: ='Dados completos'!Y195 -> 3.9 | D12: ='Dados completos'!AF195 -> 87.55 | E12: ='Dados completos'!AH195 -> 0.116048 | F12: ='Dados completos'!AI195 -> Boa | G12: ='Dados completos'!B195 -> Empresa por confirmar (gestora) | H12: ='Dados completos'!C195 -> Data Analyst Trainee, Real Assets (Lisboa) | I12: ='Dados completos'!E195 -> Serviços financeiros | J12: ='Dados completos'!F195 -> Portugal | K12: ='Dados completos'!G195 -> Lisboa | L12: ='Dados completos'!H195 -> Não indicado (provável presencial) | M12: ='Dados completos'!I195 -> Não indicado | N12: ='Dados completos'!O195 -> Não indicado | O12: ='Dados completos'!V195 -> Média-alta | P12: =IF('Dados completos'!R195="","n/d",IF('Dados completos'!R195='Dados completos'!S195,TEXT('Dados completos'!R195,"#,##0"),TEXT('Dados completos'!R195,"#,##0")&", "&TEXT('Dados completos'!S195,"#,##0"))) -> 1,100, 1,500 | Q12: ='Dados completos'!M195 -> Inglês (ver oferta) | R12: ='Dados completos'!AJ195 -> Língua-chave EN (exigência 0.8); não exige experiência prévia em finanças; aceita recém-licenciadas. | S12: ='Dados completos'!AK195 -> Por confirmar | T12: ='Dados completos'!AP195 -> Parcial (agregador/título) | U12: ='Dados completos'!AO195 -> Anúncio em plataforma | V12: =HYPERLINK('Dados completos'!AN195,"Abrir") -> Abrir
A13: ='Dados completos'!A192 -> 189 | B13: ='Dados completos'!AL192 -> Prioridade | C13: ='Dados completos'!Y192 -> 3.8 | D13: ='Dados completos'!AF192 -> 87.15 | E13: ='Dados completos'!AH192 -> 0.115664 | F13: ='Dados completos'!AI192 -> Boa | G13: ='Dados completos'!B192 -> Euronext | H13: ='Dados completos'!C192 -> Early Careers (programa de 2 anos nos mercados financeiros europeus) | I13: ='Dados completos'!E192 -> Serviços financeiros | J13: ='Dados completos'!F192 -> Portugal | K13: ='Dados completos'!G192 -> Lisboa | L13: ='Dados completos'!H192 -> Não indicado (provável presencial) | M13: ='Dados completos'!I192 -> Não indicado | N13: ='Dados completos'!O192 -> Não indicado | O13: ='Dados completos'!V192 -> Média-alta | P13: =IF('Dados completos'!R192="","n/d",IF('Dados completos'!R192='Dados completos'!S192,TEXT('Dados completos'!R192,"#,##0"),TEXT('Dados completos'!R192,"#,##0")&", "&TEXT('Dados completos'!S192,"#,##0"))) -> 1,200, 1,700 | Q13: ='Dados completos'!M192 -> Inglês obrigatório | R13: ='Dados completos'!AJ192 -> Língua-chave EN (exigência 0.9); não exige experiência prévia em finanças; aceita recém-licenciadas. | S13: ='Dados completos'!AK192 -> Por confirmar | T13: ='Dados completos'!AP192 -> Parcial (agregador/título) | U13: ='Dados completos'!AO192 -> Página de carreiras (procurar a vaga) | V13: =HYPERLINK('Dados completos'!AN192,"Abrir") -> Abrir
A14: ='Dados completos'!A221 -> 218 | B14: ='Dados completos'!AL221 -> Candidatar (reach) | C14: ='Dados completos'!Y221 -> 3.1 | D14: ='Dados completos'!AF221 -> 91.3 | E14: ='Dados completos'!AH221 -> 0.179472 | F14: ='Dados completos'!AI221 -> Boa | G14: ='Dados completos'!B221 -> Hilton | H14: ='Dados completos'!C221 -> Finance Intern / Trainee (Lisboa) | I14: ='Dados completos'!E221 -> Big corporate | J14: ='Dados completos'!F221 -> Portugal | K14: ='Dados completos'!G221 -> Lisboa | L14: ='Dados completos'!H221 -> Não indicado (provável presencial) | M14: ='Dados completos'!I221 -> Não indicado | N14: ='Dados completos'!O221 -> Não indicado | O14: ='Dados completos'!V221 -> Média | P14: =IF('Dados completos'!R221="","n/d",IF('Dados completos'!R221='Dados completos'!S221,TEXT('Dados completos'!R221,"#,##0"),TEXT('Dados completos'!R221,"#,##0")&", "&TEXT('Dados completos'!S221,"#,##0"))) -> 1,000, 1,300 | Q14: ='Dados completos'!M221 -> Inglês (ver oferta) | R14: ='Dados completos'!AJ221 -> Língua-chave EN (exigência 0.8); não exige experiência prévia em finanças; aceita recém-licenciadas. | S14: ='Dados completos'!AK221 -> Por confirmar | T14: ='Dados completos'!AP221 -> Parcial (agregador/título) | U14: ='Dados completos'!AO221 -> Anúncio em plataforma | V14: =HYPERLINK('Dados completos'!AN221,"Abrir") -> Abrir
A15: ='Dados completos'!A222 -> 219 | B15: ='Dados completos'!AL222 -> Candidatar (reach) | C15: ='Dados completos'!Y222 -> 3.1 | D15: ='Dados completos'!AF222 -> 91.3 | E15: ='Dados completos'!AH222 -> 0.179472 | F15: ='Dados completos'!AI222 -> Boa | G15: ='Dados completos'!B222 -> Solen Software Group | H15: ='Dados completos'!C222 -> Finance Internship (Lisboa) | I15: ='Dados completos'!E222 -> Startup / scale-up | J15: ='Dados completos'!F222 -> Portugal | K15: ='Dados completos'!G222 -> Lisboa | L15: ='Dados completos'!H222 -> Não indicado (provável presencial) | M15: ='Dados completos'!I222 -> Não indicado | N15: ='Dados completos'!O222 -> Não indicado | O15: ='Dados completos'!V222 -> Média | P15: =IF('Dados completos'!R222="","n/d",IF('Dados completos'!R222='Dados completos'!S222,TEXT('Dados completos'!R222,"#,##0"),TEXT('Dados completos'!R222,"#,##0")&", "&TEXT('Dados completos'!S222,"#,##0"))) -> 900, 1,200 | Q15: ='Dados completos'!M222 -> Inglês (ver oferta) | R15: ='Dados completos'!AJ222 -> Língua-chave EN (exigência 0.8); não exige experiência prévia em finanças; aceita recém-licenciadas. | S15: ='Dados completos'!AK222 -> Por confirmar | T15: ='Dados completos'!AP222 -> Parcial (agregador/título) | U15: ='Dados completos'!AO222 -> Anúncio em plataforma | V15: =HYPERLINK('Dados completos'!AN222,"Abrir") -> Abrir
A16: ='Dados completos'!A180 -> 177 | B16: ='Dados completos'!AL180 -> Prioridade | C16: ='Dados completos'!Y180 -> 3.7 | D16: ='Dados completos'!AF180 -> 89.5 | E16: ='Dados completos'!AH180 -> 0.11792 | F16: ='Dados completos'!AI180 -> Boa | G16: ='Dados completos'!B180 -> BNP Paribas CIB | H16: ='Dados completos'!C180 -> Strategy and Strategic Investments Trainee (Global Markets, Lisboa) | I16: ='Dados completos'!E180 -> Banca comercial | J16: ='Dados completos'!F180 -> Portugal | K16: ='Dados completos'!G180 -> Lisboa | L16: ='Dados completos'!H180 -> Não indicado (provável presencial) | M16: ='Dados completos'!I180 -> Não indicado | N16: ='Dados completos'!O180 -> Não indicado | O16: ='Dados completos'!V180 -> Média-alta | P16: =IF('Dados completos'!R180="","n/d",IF('Dados completos'!R180='Dados completos'!S180,TEXT('Dados completos'!R180,"#,##0"),TEXT('Dados completos'!R180,"#,##0")&", "&TEXT('Dados completos'!S180,"#,##0"))) -> 1,100, 1,500 | Q16: ='Dados completos'!M180 -> Inglês (candidatura só em inglês) | R16: ='Dados completos'!AJ180 -> Língua-chave EN (exigência 1); não exige experiência prévia em finanças; aceita recém-licenciadas. | S16: ='Dados completos'!AK180 -> Aberta (prazo não indicado) | T16: ='Dados completos'!AP180 -> Verificada na página | U16: ='Dados completos'!AO180 -> Direto (site/ATS da empresa) | V16: =HYPERLINK('Dados completos'!AN180,"Abrir") -> Abrir
A17: ='Dados completos'!A161 -> 158 | B17: ='Dados completos'!AL161 -> Prioridade | C17: ='Dados completos'!Y161 -> 3.6 | D17: ='Dados completos'!AF161 -> 87.25 | E17: ='Dados completos'!AH161 -> 0.11576 | F17: ='Dados completos'!AI161 -> Boa | G17: ='Dados completos'!B161 -> BNP Paribas | H17: ='Dados completos'!C161 -> Trainee Fixed Income Analyst (Lisboa) | I17: ='Dados completos'!E161 -> Banca de investimento | J17: ='Dados completos'!F161 -> Portugal | K17: ='Dados completos'!G161 -> Lisboa | L17: ='Dados completos'!H161 -> Não indicado (provável presencial) | M17: ='Dados completos'!I161 -> Não indicado | N17: ='Dados completos'!O161 -> Não indicado | O17: ='Dados completos'!V161 -> Média-alta | P17: =IF('Dados completos'!R161="","n/d",IF('Dados completos'!R161='Dados completos'!S161,TEXT('Dados completos'!R161,"#,##0"),TEXT('Dados completos'!R161,"#,##0")&", "&TEXT('Dados completos'!S161,"#,##0"))) -> 1,000, 1,400 | Q17: ='Dados completos'!M161 -> Inglês (ver oferta) | R17: ='Dados completos'!AJ161 -> Língua-chave EN (exigência 1); não exige experiência prévia em finanças; aceita recém-licenciadas. | S17: ='Dados completos'!AK161 -> Por confirmar | T17: ='Dados completos'!AP161 -> Parcial (agregador/título) | U17: ='Dados completos'!AO161 -> Direto (site/ATS da empresa) | V17: =HYPERLINK('Dados completos'!AN161,"Abrir") -> Abrir
A18: ='Dados completos'!A162 -> 159 | B18: ='Dados completos'!AL162 -> Prioridade | C18: ='Dados completos'!Y162 -> 3.6 | D18: ='Dados completos'!AF162 -> 87.25 | E18: ='Dados completos'!AH162 -> 0.11576 | F18: ='Dados completos'!AI162 -> Boa | G18: ='Dados completos'!B162 -> BNP Paribas | H18: ='Dados completos'!C162 -> Financial & International Markets Trainee (Lisboa) | I18: ='Dados completos'!E162 -> Banca de investimento | J18: ='Dados completos'!F162 -> Portugal | K18: ='Dados completos'!G162 -> Lisboa | L18: ='Dados completos'!H162 -> Não indicado (provável presencial) | M18: ='Dados completos'!I162 -> Não indicado | N18: ='Dados completos'!O162 -> Não indicado | O18: ='Dados completos'!V162 -> Média-alta | P18: =IF('Dados completos'!R162="","n/d",IF('Dados completos'!R162='Dados completos'!S162,TEXT('Dados completos'!R162,"#,##0"),TEXT('Dados completos'!R162,"#,##0")&", "&TEXT('Dados completos'!S162,"#,##0"))) -> 1,000, 1,400 | Q18: ='Dados completos'!M162 -> Inglês (ver oferta) | R18: ='Dados completos'!AJ162 -> Língua-chave EN (exigência 1); não exige experiência prévia em finanças; aceita recém-licenciadas. | S18: ='Dados completos'!AK162 -> Por confirmar | T18: ='Dados completos'!AP162 -> Parcial (agregador/título) | U18: ='Dados completos'!AO162 -> Direto (site/ATS da empresa) | V18: =HYPERLINK('Dados completos'!AN162,"Abrir") -> Abrir
A19: ='Dados completos'!A183 -> 180 | B19: ='Dados completos'!AL183 -> Prioridade | C19: ='Dados completos'!Y183 -> 3.5 | D19: ='Dados completos'!AF183 -> 92.5 | E19: ='Dados completos'!AH183 -> 0.1208 | F19: ='Dados completos'!AI183 -> Boa | G19: ='Dados completos'!B183 -> Deloitte Portugal | H19: ='Dados completos'!C183 -> Hello World 26/27, New Graduates (Financial Advisory, Risk Advisory, Consulting, Audit, Tax) | I19: ='Dados completos'!E183 -> Big 4 / consultoria | J19: ='Dados completos'!F183 -> Portugal | K19: ='Dados completos'!G183 -> Lisboa | L19: ='Dados completos'!H183 -> Não indicado (provável presencial) | M19: ='Dados completos'!I183 -> Não indicado | N19: ='Dados completos'!O183 -> Não indicado | O19: ='Dados completos'!V183 -> Média-alta | P19: =IF('Dados completos'!R183="","n/d",IF('Dados completos'!R183='Dados completos'!S183,TEXT('Dados completos'!R183,"#,##0"),TEXT('Dados completos'!R183,"#,##0")&", "&TEXT('Dados completos'!S183,"#,##0"))) -> 1,200, 1,500 | Q19: ='Dados completos'!M183 -> Português e inglês | R19: ='Dados completos'!AJ183 -> Língua-chave PT (exigência 0.3); não exige experiência prévia em finanças; aceita recém-licenciadas. | S19: ='Dados completos'!AK183 -> Aberta (prazo não indicado) | T19: ='Dados completos'!AP183 -> Verificada na página | U19: ='Dados completos'!AO183 -> Direto (site/ATS da empresa) | V19: =HYPERLINK('Dados completos'!AN183,"Abrir") -> Abrir
A20: ='Dados completos'!A184 -> 181 | B20: ='Dados completos'!AL184 -> Prioridade | C20: ='Dados completos'!Y184 -> 3.5 | D20: ='Dados completos'!AF184 -> 92.5 | E20: ='Dados completos'!AH184 -> 0.1208 | F20: ='Dados completos'!AI184 -> Boa | G20: ='Dados completos'!B184 -> Deloitte Portugal | H20: ='Dados completos'!C184 -> Candidatura espontânea (Lisboa) | I20: ='Dados completos'!E184 -> Big 4 / consultoria | J20: ='Dados completos'!F184 -> Portugal | K20: ='Dados completos'!G184 -> Lisboa | L20: ='Dados completos'!H184 -> Não indicado (provável presencial) | M20: ='Dados completos'!I184 -> Não indicado | N20: ='Dados completos'!O184 -> Não indicado | O20: ='Dados completos'!V184 -> Média-alta | P20: =IF('Dados completos'!R184="","n/d",IF('Dados completos'!R184='Dados completos'!S184,TEXT('Dados completos'!R184,"#,##0"),TEXT('Dados completos'!R184,"#,##0")&", "&TEXT('Dados completos'!S184,"#,##0"))) -> 1,200, 1,500 | Q20: ='Dados completos'!M184 -> Inglês (ver oferta) | R20: ='Dados completos'!AJ184 -> Língua-chave PT (exigência 0.3); não exige experiência prévia em finanças; aceita recém-licenciadas. | S20: ='Dados completos'!AK184 -> Aberta (prazo não indicado) | T20: ='Dados completos'!AP184 -> Parcial (agregador/título) | U20: ='Dados completos'!AO184 -> Direto (site/ATS da empresa) | V20: =HYPERLINK('Dados completos'!AN184,"Abrir") -> Abrir
A21: ='Dados completos'!A187 -> 184 | B21: ='Dados completos'!AL187 -> Prioridade | C21: ='Dados completos'!Y187 -> 3.5 | D21: ='Dados completos'!AF187 -> 92.5 | E21: ='Dados completos'!AH187 -> 0.1208 | F21: ='Dados completos'!AI187 -> Boa | G21: ='Dados completos'!B187 -> EY Portugal | H21: ='Dados completos'!C187 -> Oportunidades de início de carreira (estágios e programas) | I21: ='Dados completos'!E187 -> Big 4 / consultoria | J21: ='Dados completos'!F187 -> Portugal | K21: ='Dados completos'!G187 -> Lisboa | L21: ='Dados completos'!H187 -> Não indicado (provável presencial) | M21: ='Dados completos'!I187 -> Não indicado | N21: ='Dados completos'!O187 -> Não indicado | O21: ='Dados completos'!V187 -> Média-alta | P21: =IF('Dados completos'!R187="","n/d",IF('Dados completos'!R187='Dados completos'!S187,TEXT('Dados completos'!R187,"#,##0"),TEXT('Dados completos'!R187,"#,##0")&", "&TEXT('Dados completos'!S187,"#,##0"))) -> 1,100, 1,400 | Q21: ='Dados completos'!M187 -> Inglês (ver oferta) | R21: ='Dados completos'!AJ187 -> Língua-chave PT (exigência 0.3); não exige experiência prévia em finanças; aceita recém-licenciadas. | S21: ='Dados completos'!AK187 -> Aberta (prazo não indicado) | T21: ='Dados completos'!AP187 -> Parcial (agregador/título) | U21: ='Dados completos'!AO187 -> Página de carreiras (procurar a vaga) | V21: =HYPERLINK('Dados completos'!AN187,"Abrir") -> Abrir
A22: ='Dados completos'!A163 -> 160 | B22: ='Dados completos'!AL163 -> Reserva | C22: ='Dados completos'!Y163 -> 2.9 | D22: ='Dados completos'!AF163 -> 92.5 | E22: ='Dados completos'!AH163 -> 0.1812 | F22: ='Dados completos'!AI163 -> Boa | G22: ='Dados completos'!B163 -> Accenture | H22: ='Dados completos'!C163 -> Consulting Graduate Programme, January 2027 (Lisboa) | I22: ='Dados completos'!E163 -> Big 4 / consultoria | J22: ='Dados completos'!F163 -> Portugal | K22: ='Dados completos'!G163 -> Lisboa | L22: ='Dados completos'!H163 -> Não indicado (provável presencial) | M22: ='Dados completos'!I163 -> Jan 2027 | N22: ='Dados completos'!O163 -> Não indicado | O22: ='Dados completos'!V163 -> Média | P22: =IF('Dados completos'!R163="","n/d",IF('Dados completos'!R163='Dados completos'!S163,TEXT('Dados completos'!R163,"#,##0"),TEXT('Dados completos'!R163,"#,##0")&", "&TEXT('Dados completos'!S163,"#,##0"))) -> 1,000, 1,400 | Q22: ='Dados completos'!M163 -> Inglês (ver oferta) | R22: ='Dados completos'!AJ163 -> Língua-chave EN (exigência 1); não exige experiência prévia em finanças; aceita recém-licenciadas. | S22: ='Dados completos'!AK163 -> Por confirmar | T22: ='Dados completos'!AP163 -> Parcial (agregador/título) | U22: ='Dados completos'!AO163 -> Direto (site/ATS da empresa) | V22: =HYPERLINK('Dados completos'!AN163,"Abrir") -> Abrir
A23: ='Dados completos'!A176 -> 173 | B23: ='Dados completos'!AL176 -> Reserva | C23: ='Dados completos'!Y176 -> 2.9 | D23: ='Dados completos'!AF176 -> 92.5 | E23: ='Dados completos'!AH176 -> 0.1812 | F23: ='Dados completos'!AI176 -> Boa | G23: ='Dados completos'!B176 -> Santander Portugal | H23: ='Dados completos'!C176 -> Estágio, Área de Universidades (Evergreen) | I23: ='Dados completos'!E176 -> Banca comercial | J23: ='Dados completos'!F176 -> Portugal | K23: ='Dados completos'!G176 -> Lisboa | L23: ='Dados completos'!H176 -> Não indicado (provável presencial) | M23: ='Dados completos'!I176 -> Não indicado | N23: ='Dados completos'!O176 -> Não indicado | O23: ='Dados completos'!V176 -> Média | P23: =IF('Dados completos'!R176="","n/d",IF('Dados completos'!R176='Dados completos'!S176,TEXT('Dados completos'!R176,"#,##0"),TEXT('Dados completos'!R176,"#,##0")&", "&TEXT('Dados completos'!S176,"#,##0"))) -> 1,000, 1,300 | Q23: ='Dados completos'!M176 -> Inglês (ver oferta) | R23: ='Dados completos'!AJ176 -> Língua-chave PT (exigência 0.3); não exige experiência prévia em finanças; aceita recém-licenciadas. | S23: ='Dados completos'!AK176 -> Por confirmar | T23: ='Dados completos'!AP176 -> Parcial (agregador/título) | U23: ='Dados completos'!AO176 -> Direto (site/ATS da empresa) | V23: =HYPERLINK('Dados completos'!AN176,"Abrir") -> Abrir
A24: ='Dados completos'!A188 -> 185 | B24: ='Dados completos'!AL188 -> Reserva | C24: ='Dados completos'!Y188 -> 2.9 | D24: ='Dados completos'!AF188 -> 92.5 | E24: ='Dados completos'!AH188 -> 0.1812 | F24: ='Dados completos'!AI188 -> Boa | G24: ='Dados completos'!B188 -> EY Portugal | H24: ='Dados completos'!C188 -> Estágios, Confirmation Team (Lisboa e Viseu) | I24: ='Dados completos'!E188 -> Big 4 / consultoria | J24: ='Dados completos'!F188 -> Portugal | K24: ='Dados completos'!G188 -> Lisboa | L24: ='Dados completos'!H188 -> Não indicado (provável presencial) | M24: ='Dados completos'!I188 -> Não indicado | N24: ='Dados completos'!O188 -> Não indicado | O24: ='Dados completos'!V188 -> Média | P24: =IF('Dados completos'!R188="","n/d",IF('Dados completos'!R188='Dados completos'!S188,TEXT('Dados completos'!R188,"#,##0"),TEXT('Dados completos'!R188,"#,##0")&", "&TEXT('Dados completos'!S188,"#,##0"))) -> 1,000, 1,300 | Q24: ='Dados completos'!M188 -> Inglês (ver oferta) | R24: ='Dados completos'!AJ188 -> Língua-chave PT (exigência 0.3); não exige experiência prévia em finanças; aceita recém-licenciadas. | S24: ='Dados completos'!AK188 -> Por confirmar | T24: ='Dados completos'!AP188 -> Parcial (agregador/título) | U24: ='Dados completos'!AO188 -> Direto (site/ATS da empresa) | V24: =HYPERLINK('Dados completos'!AN188,"Abrir") -> Abrir
A25: ='Dados completos'!A220 -> 217 | B25: ='Dados completos'!AL220 -> Reserva | C25: ='Dados completos'!Y220 -> 2.9 | D25: ='Dados completos'!AF220 -> 92.5 | E25: ='Dados completos'!AH220 -> 0.1812 | F25: ='Dados completos'!AI220 -> Boa | G25: ='Dados completos'!B220 -> DHL | H25: ='Dados completos'!C220 -> Estágios locais, AIESEC e programa G100 (EMEA) | I25: ='Dados completos'!E220 -> Big corporate | J25: ='Dados completos'!F220 -> Portugal | K25: ='Dados completos'!G220 -> Lisboa | L25: ='Dados completos'!H220 -> Não indicado (provável presencial) | M25: ='Dados completos'!I220 -> Não indicado | N25: ='Dados completos'!O220 -> Não indicado | O25: ='Dados completos'!V220 -> Média | P25: =IF('Dados completos'!R220="","n/d",IF('Dados completos'!R220='Dados completos'!S220,TEXT('Dados completos'!R220,"#,##0"),TEXT('Dados completos'!R220,"#,##0")&", "&TEXT('Dados completos'!S220,"#,##0"))) -> 1,000, 1,400 | Q25: ='Dados completos'!M220 -> Inglês (ver oferta) | R25: ='Dados completos'!AJ220 -> Língua-chave PT (exigência 0.3); não exige experiência prévia em finanças; aceita recém-licenciadas. | S25: ='Dados completos'!AK220 -> Por confirmar | T25: ='Dados completos'!AP220 -> Parcial (agregador/título) | U25: ='Dados completos'!AO220 -> Página de carreiras (procurar a vaga) | V25: =HYPERLINK('Dados completos'!AN220,"Abrir") -> Abrir
A26: ='Dados completos'!A193 -> 190 | B26: ='Dados completos'!AL193 -> Candidatar (reach) | C26: ='Dados completos'!Y193 -> 3.1 | D26: ='Dados completos'!AF193 -> 72.6 | E26: ='Dados completos'!AH193 -> 0.101696 | F26: ='Dados completos'!AI193 -> Boa | G26: ='Dados completos'!B193 -> Euronext | H26: ='Dados completos'!C193 -> Outsourcing Analyst (VIE, Porto) | I26: ='Dados completos'!E193 -> Serviços financeiros | J26: ='Dados completos'!F193 -> Portugal | K26: ='Dados completos'!G193 -> Porto | L26: ='Dados completos'!H193 -> Não indicado (provável presencial) | M26: ='Dados completos'!I193 -> Não indicado | N26: ='Dados completos'!O193 -> Não indicado | O26: ='Dados completos'!V193 -> Média-alta | P26: =IF('Dados completos'!R193="","n/d",IF('Dados completos'!R193='Dados completos'!S193,TEXT('Dados completos'!R193,"#,##0"),TEXT('Dados completos'!R193,"#,##0")&", "&TEXT('Dados completos'!S193,"#,##0"))) -> 1,300, 1,800 | Q26: ='Dados completos'!M193 -> Inglês (ver oferta) | R26: ='Dados completos'!AJ193 -> Língua-chave FR (exigência 0.4); não exige experiência prévia em finanças; aceita recém-licenciadas. | S26: ='Dados completos'!AK193 -> Por confirmar | T26: ='Dados completos'!AP193 -> Parcial (agregador/título) | U26: ='Dados completos'!AO193 -> Anúncio em plataforma | V26: =HYPERLINK('Dados completos'!AN193,"Abrir") -> Abrir
A27: ='Dados completos'!A198 -> 195 | B27: ='Dados completos'!AL198 -> Reserva | C27: ='Dados completos'!Y198 -> 2.7 | D27: ='Dados completos'!AF198 -> 88.3 | E27: ='Dados completos'!AH198 -> 0.175152 | F27: ='Dados completos'!AI198 -> Boa | G27: ='Dados completos'!B198 -> Empresa por confirmar | H27: ='Dados completos'!C198 -> AML Analyst, Academy Program (Lisboa) | I27: ='Dados completos'!E198 -> Serviços financeiros | J27: ='Dados completos'!F198 -> Portugal | K27: ='Dados completos'!G198 -> Lisboa | L27: ='Dados completos'!H198 -> Não indicado (provável presencial) | M27: ='Dados completos'!I198 -> Não indicado | N27: ='Dados completos'!O198 -> Não indicado | O27: ='Dados completos'!V198 -> Média | P27: =IF('Dados completos'!R198="","n/d",IF('Dados completos'!R198='Dados completos'!S198,TEXT('Dados completos'!R198,"#,##0"),TEXT('Dados completos'!R198,"#,##0")&", "&TEXT('Dados completos'!S198,"#,##0"))) -> 1,000, 1,400 | Q27: ='Dados completos'!M198 -> Inglês (ver oferta) | R27: ='Dados completos'!AJ198 -> Língua-chave EN (exigência 0.8); não exige experiência prévia em finanças; aceita recém-licenciadas. | S27: ='Dados completos'!AK198 -> Por confirmar | T27: ='Dados completos'!AP198 -> Parcial (agregador/título) | U27: ='Dados completos'!AO198 -> Anúncio em plataforma | V27: =HYPERLINK('Dados completos'!AN198,"Abrir") -> Abrir
A28: ='Dados completos'!A199 -> 196 | B28: ='Dados completos'!AL199 -> Reserva | C28: ='Dados completos'!Y199 -> 2.7 | D28: ='Dados completos'!AF199 -> 88.3 | E28: ='Dados completos'!AH199 -> 0.175152 | F28: ='Dados completos'!AI199 -> Boa | G28: ='Dados completos'!B199 -> Empresa por confirmar | H28: ='Dados completos'!C199 -> Business Continuity Analyst Trainee (Lisboa) | I28: ='Dados completos'!E199 -> Serviços financeiros | J28: ='Dados completos'!F199 -> Portugal | K28: ='Dados completos'!G199 -> Lisboa | L28: ='Dados completos'!H199 -> Não indicado (provável presencial) | M28: ='Dados completos'!I199 -> Não indicado | N28: ='Dados completos'!O199 -> Não indicado | O28: ='Dados completos'!V199 -> Média | P28: =IF('Dados completos'!R199="","n/d",IF('Dados completos'!R199='Dados completos'!S199,TEXT('Dados completos'!R199,"#,##0"),TEXT('Dados completos'!R199,"#,##0")&", "&TEXT('Dados completos'!S199,"#,##0"))) -> 1,000, 1,400 | Q28: ='Dados completos'!M199 -> Inglês (ver oferta) | R28: ='Dados completos'!AJ199 -> Língua-chave EN (exigência 0.8); não exige experiência prévia em finanças; aceita recém-licenciadas. | S28: ='Dados completos'!AK199 -> Por confirmar | T28: ='Dados completos'!AP199 -> Parcial (agregador/título) | U28: ='Dados completos'!AO199 -> Anúncio em plataforma | V28: =HYPERLINK('Dados completos'!AN199,"Abrir") -> Abrir
A29: ='Dados completos'!A200 -> 197 | B29: ='Dados completos'!AL200 -> Reserva | C29: ='Dados completos'!Y200 -> 2.7 | D29: ='Dados completos'!AF200 -> 88.3 | E29: ='Dados completos'!AH200 -> 0.175152 | F29: ='Dados completos'!AI200 -> Boa | G29: ='Dados completos'!B200 -> Empresa por confirmar | H29: ='Dados completos'!C200 -> Data Quality Trainee (Lisboa) | I29: ='Dados completos'!E200 -> Serviços financeiros | J29: ='Dados completos'!F200 -> Portugal | K29: ='Dados completos'!G200 -> Lisboa | L29: ='Dados completos'!H200 -> Não indicado (provável presencial) | M29: ='Dados completos'!I200 -> Não indicado | N29: ='Dados completos'!O200 -> Não indicado | O29: ='Dados completos'!V200 -> Média | P29: =IF('Dados completos'!R200="","n/d",IF('Dados completos'!R200='Dados completos'!S200,TEXT('Dados completos'!R200,"#,##0"),TEXT('Dados completos'!R200,"#,##0")&", "&TEXT('Dados completos'!S200,"#,##0"))) -> 1,000, 1,400 | Q29: ='Dados completos'!M200 -> Inglês (ver oferta) | R29: ='Dados completos'!AJ200 -> Língua-chave EN (exigência 0.8); não exige experiência prévia em finanças; aceita recém-licenciadas. | S29: ='Dados completos'!AK200 -> Por confirmar | T29: ='Dados completos'!AP200 -> Parcial (agregador/título) | U29: ='Dados completos'!AO200 -> Anúncio em plataforma | V29: =HYPERLINK('Dados completos'!AN200,"Abrir") -> Abrir
A30: ='Dados completos'!A39 -> 36 | B30: ='Dados completos'!AL39 -> Reserva | C30: ='Dados completos'!Y39 -> 2.8 | D30: ='Dados completos'!AF39 -> 88 | E30: ='Dados completos'!AH39 -> 0.17472 | F30: ='Dados completos'!AI39 -> Boa | G30: ='Dados completos'!B39 -> Banco Santander Totta | H30: ='Dados completos'!C39 -> Estágio, Área de Fomento à Construção (Lisboa) | I30: ='Dados completos'!E39 -> Banca comercial | J30: ='Dados completos'!F39 -> Portugal | K30: ='Dados completos'!G39 -> Lisboa | L30: ='Dados completos'!H39 -> Não indicado (provável presencial) | M30: ='Dados completos'!I39 -> Não indicado | N30: ='Dados completos'!O39 -> Não indicado | O30: ='Dados completos'!V39 -> Média | P30: =IF('Dados completos'!R39="","n/d",IF('Dados completos'!R39='Dados completos'!S39,TEXT('Dados completos'!R39,"#,##0"),TEXT('Dados completos'!R39,"#,##0")&", "&TEXT('Dados completos'!S39,"#,##0"))) -> 1,000, 1,300 | Q30: ='Dados completos'!M39 -> Português | R30: ='Dados completos'!AJ39 -> Língua-chave PT (exigência 1); não exige experiência prévia em finanças; aceita recém-licenciadas. | S30: ='Dados completos'!AK39 -> Por confirmar | T30: ='Dados completos'!AP39 -> Parcial (agregador/título) | U30: ='Dados completos'!AO39 -> Página de carreiras (procurar a vaga) | V30: =HYPERLINK('Dados completos'!AN39,"Abrir") -> Abrir
A31: ='Dados completos'!A196 -> 193 | B31: ='Dados completos'!AL196 -> Candidatar (reach) | C31: ='Dados completos'!Y196 -> 3.3 | D31: ='Dados completos'!AF196 -> 87.55 | E31: ='Dados completos'!AH196 -> 0.116048 | F31: ='Dados completos'!AI196 -> Boa | G31: ='Dados completos'!B196 -> Empresa por confirmar | H31: ='Dados completos'!C196 -> Data Analyst Trainee (Lisboa) | I31: ='Dados completos'!E196 -> Serviços financeiros | J31: ='Dados completos'!F196 -> Portugal | K31: ='Dados completos'!G196 -> Lisboa | L31: ='Dados completos'!H196 -> Não indicado (provável presencial) | M31: ='Dados completos'!I196 -> Não indicado | N31: ='Dados completos'!O196 -> Não indicado | O31: ='Dados completos'!V196 -> Média-alta | P31: =IF('Dados completos'!R196="","n/d",IF('Dados completos'!R196='Dados completos'!S196,TEXT('Dados completos'!R196,"#,##0"),TEXT('Dados completos'!R196,"#,##0")&", "&TEXT('Dados completos'!S196,"#,##0"))) -> 1,100, 1,500 | Q31: ='Dados completos'!M196 -> Inglês (ver oferta) | R31: ='Dados completos'!AJ196 -> Língua-chave EN (exigência 0.8); não exige experiência prévia em finanças; aceita recém-licenciadas. | S31: ='Dados completos'!AK196 -> Por confirmar | T31: ='Dados completos'!AP196 -> Parcial (agregador/título) | U31: ='Dados completos'!AO196 -> Anúncio em plataforma | V31: =HYPERLINK('Dados completos'!AN196,"Abrir") -> Abrir
A32: ='Dados completos'!A189 -> 186 | B32: ='Dados completos'!AL189 -> Candidatar (reach) | C32: ='Dados completos'!Y189 -> 3.2 | D32: ='Dados completos'!AF189 -> 85.3 | E32: ='Dados completos'!AH189 -> 0.113888 | F32: ='Dados completos'!AI189 -> Boa | G32: ='Dados completos'!B189 -> Marsh | H32: ='Dados completos'!C189 -> Junior Analyst (estágio de 6 meses, Lisboa) | I32: ='Dados completos'!E189 -> Big 4 / consultoria | J32: ='Dados completos'!F189 -> Portugal | K32: ='Dados completos'!G189 -> Lisboa | L32: ='Dados completos'!H189 -> Não indicado (provável presencial) | M32: ='Dados completos'!I189 -> Não indicado | N32: ='Dados completos'!O189 -> Não indicado | O32: ='Dados completos'!V189 -> Média-alta | P32: =IF('Dados completos'!R189="","n/d",IF('Dados completos'!R189='Dados completos'!S189,TEXT('Dados completos'!R189,"#,##0"),TEXT('Dados completos'!R189,"#,##0")&", "&TEXT('Dados completos'!S189,"#,##0"))) -> 1,000, 1,400 | Q32: ='Dados completos'!M189 -> Inglês (ver oferta) | R32: ='Dados completos'!AJ189 -> Língua-chave EN (exigência 0.8); não exige experiência prévia em finanças; aceita recém-licenciadas. | S32: ='Dados completos'!AK189 -> Por confirmar | T32: ='Dados completos'!AP189 -> Parcial (agregador/título) | U32: ='Dados completos'!AO189 -> Anúncio em plataforma | V32: =HYPERLINK('Dados completos'!AN189,"Abrir") -> Abrir
A33: ='Dados completos'!A190 -> 187 | B33: ='Dados completos'!AL190 -> Candidatar (reach) | C33: ='Dados completos'!Y190 -> 3.2 | D33: ='Dados completos'!AF190 -> 85.15 | E33: ='Dados completos'!AH190 -> 0.113744 | F33: ='Dados completos'!AI190 -> Boa | G33: ='Dados completos'!B190 -> Marsh | H33: ='Dados completos'!C190 -> Insured Consulting Analyst, Ireland (estágio, Lisboa) | I33: ='Dados completos'!E190 -> Big 4 / consultoria | J33: ='Dados completos'!F190 -> Portugal | K33: ='Dados completos'!G190 -> Lisboa | L33: ='Dados completos'!H190 -> Não indicado (provável presencial) | M33: ='Dados completos'!I190 -> Não indicado | N33: ='Dados completos'!O190 -> Não indicado | O33: ='Dados completos'!V190 -> Média-alta | P33: =IF('Dados completos'!R190="","n/d",IF('Dados completos'!R190='Dados completos'!S190,TEXT('Dados completos'!R190,"#,##0"),TEXT('Dados completos'!R190,"#,##0")&", "&TEXT('Dados completos'!S190,"#,##0"))) -> 1,000, 1,400 | Q33: ='Dados completos'!M190 -> Inglês (ver oferta) | R33: ='Dados completos'!AJ190 -> Língua-chave EN (exigência 0.9); não exige experiência prévia em finanças; aceita recém-licenciadas. | S33: ='Dados completos'!AK190 -> Por confirmar | T33: ='Dados completos'!AP190 -> Parcial (agregador/título) | U33: ='Dados completos'!AO190 -> Anúncio em plataforma | V33: =HYPERLINK('Dados completos'!AN190,"Abrir") -> Abrir
A34: ='Dados completos'!A203 -> 200 | B34: ='Dados completos'!AL203 -> Candidatar (reach) | C34: ='Dados completos'!Y203 -> 3 | D34: ='Dados completos'!AF203 -> 77.75 | E34: ='Dados completos'!AH203 -> 0.10664 | F34: ='Dados completos'!AI203 -> Boa | G34: ='Dados completos'!B203 -> UNICRE | H34: ='Dados completos'!C203 -> Unlocker Junior Controller (Planeamento e Controlo de Gestão) | I34: ='Dados completos'!E203 -> Serviços financeiros | J34: ='Dados completos'!F203 -> Portugal | K34: ='Dados completos'!G203 -> Lisboa | L34: ='Dados completos'!H203 -> Não indicado (provável presencial) | M34: ='Dados completos'!I203 -> Não indicado | N34: ='Dados completos'!O203 -> 46314 | O34: ='Dados completos'!V203 -> Média-alta | P34: =IF('Dados completos'!R203="","n/d",IF('Dados completos'!R203='Dados completos'!S203,TEXT('Dados completos'!R203,"#,##0"),TEXT('Dados completos'!R203,"#,##0")&", "&TEXT('Dados completos'!S203,"#,##0"))) -> 1,200, 1,600 | Q34: ='Dados completos'!M203 -> Português e inglês | R34: ='Dados completos'!AJ203 -> Língua-chave PT (exigência 0.3); experiência prévia em finanças valorizada, CV tem pouca. | S34: ='Dados completos'!AK203 -> Aberta, prazo definido | T34: ='Dados completos'!AP203 -> Verificada na página | U34: ='Dados completos'!AO203 -> Anúncio em plataforma | V34: =HYPERLINK('Dados completos'!AN203,"Abrir") -> Abrir
